{"errorMessage":"Lambda process returned error status code: 1. Result: {\"errorMessage\":\"2021-06-09T03:08:52.641Z 212db77d-e59b-18f9-0d06-714399a6931d Task timed out after 3.00 seconds\"}. Output:\n\u001b[32mSTART RequestId: 212db77d-e59b-18f9-0d06-714399a6931d Version: $LATEST\u001b[0m\n2021-06-09T03:08:49.466Z\t212db77d-e59b-18f9-0d06-714399a6931d\tINFO\tCalled function  http://172.18.0.2:4566\n2021-06-09T03:08:52.639Z\t212db77d-e59b-18f9-0d06-714399a6931d\tERROR\tError: connect ECONNREFUSED 169.254.169.254:80\n    at TCPConnectWrap.afterConnect [as oncomplete] (net.js:1144:16) {\n  message: 'Missing credentials in config, if using AWS_CONFIG_FILE, set AWS_SDK_LOAD_CONFIG=1',\n  errno: 'ECONNREFUSED',\n  code: 'CredentialsError',\n  syscall: 'connect',\n  address: '169.254.169.254',\n  port: 80,\n  time: 2021-06-09T03:08:52.634Z,\n  originalError: {\n    message: 'Could not load credentials from any providers',\n    errno: 'ECONNREFUSED',\n    code: 'CredentialsError',\n    syscall: 'connect',\n    address: '169.254.169.254',\n    port: 80,\n    time: 2021-06-09T03:08:52.634Z,\n    originalError: {\n      message: 'EC2 Metadata roleName request returned error',\n      errno: 'ECONNREFUSED',\n      code: 'ECONNREFUSED',\n      syscall: 'connect',\n      address: '169.254.169.254',\n      port: 80,\n      time: 2021-06-09T03:08:52.634Z,\n      originalError: [Object]\n    }\n  }\n}\n\u001b[32mEND RequestId: 212db77d-e59b-18f9-0d06-714399a6931d\u001b[0m\n\u001b[32mREPORT RequestId: 212db77d-e59b-18f9-0d06-714399a6931d\tInit Duration: 437.81 ms\tDuration: 3000.00 ms\tBilled Duration: 3000 ms\tMemory Size: 1536 MB\tMax Memory Used: 57 MB\t\u001b[0m","errorType":"InvocationException","stackTrace":["  File \"/opt/code/localstack/localstack/services/awslambda/lambda_api.py\", line 602, in run_lambda\n    result = LAMBDA_EXECUTOR.execute(func_arn, func_details, event, context=context,\n","  File \"/opt/code/localstack/localstack/services/awslambda/lambda_executors.py\", line 179, in execute\n    return do_execute()\n","  File \"/opt/code/localstack/localstack/services/awslambda/lambda_executors.py\", line 171, in do_execute\n    return _run(func_arn=func_arn)\n","  File \"/opt/code/localstack/localstack/utils/cloudwatch/cloudwatch_util.py\", line 149, in wrapped\n    raise e\n","  File \"/opt/code/localstack/localstack/utils/cloudwatch/cloudwatch_util.py\", line 145, in wrapped\n    result = func(*args, **kwargs)\n","  File \"/opt/code/localstack/localstack/services/awslambda/lambda_executors.py\", line 162, in _run\n    raise e\n","  File \"/opt/code/localstack/localstack/services/awslambda/lambda_executors.py\", line 150, in _run\n    result = self._execute(func_arn, func_details, event, context, version)\n","  File \"/opt/code/localstack/localstack/services/awslambda/lambda_executors.py\", line 334, in _execute\n    result = self.run_lambda_executor(cmd, stdin, env_vars=environment, func_details=func_details)\n","  File \"/opt/code/localstack/localstack/services/awslambda/lambda_executors.py\", line 234, in run_lambda_executor\n    raise InvocationException('Lambda process returned error status code: %s. Result: %s. Output:\\n%s' %\n"]}
